Workbook

Sheet Dashboard
B2: DASHBOARD - CONTROLE DE FORNOS
B3: =" Atualizado em "&TEXT(TODAY(),"dd/mm/yyyy")&" - Total: "&COUNTA(tblFornos[ID])&" registros"
B5: TOTAL REGISTROS | D5: FORNOS DISTINTOS | G5: FALHAS | I5: OPERACOES | L5: MES + ATIVO
B6: =COUNTA(tblFornos[ID]) | D6: =SUMPRODUCT((tblFornos[Forno]<>"")/COUNTIF(tblFornos[Forno],tblFornos[Forno]&"")) | G6: =COUNTIFS(tblFornos[Tipo],"Falha") | I6: =COUNTIFS(tblFornos[Tipo],"Operacao") | L6: =IFERROR(INDEX(_Dados!J2:J13,MATCH(MAX(_Dados!L2:L13),_Dados!L2:L13,0)),"-")
B9: REGISTROS POR MES | G9: TOP 10 DIAS COM MAIS REGISTROS | L9: POR TIPO
B26: RESUMO POR MES E TIPO
B27: Mes | C27: Operacao | E27: Manutencao | G27: Falha | I27: Inspecao | L27: TOTAL
B28: Janeiro | C28: =COUNTIFS(tblFornos[Tipo],"Operacao",tblFornos[Data],">="&DATE(YEAR(TODAY()),1,1),tblFornos[Data],"<"&DATE(YEAR(TODAY()),2,1)) | E28: =COUNTIFS(tblFornos[Tipo],"Manutencao",tblFornos[Data],">="&DATE(YEAR(TODAY()),1,1),tblFornos[Data],"<"&DATE(YEAR(TODAY()),2,1)) | G28: =COUNTIFS(tblFornos[Tipo],"Falha",tblFornos[Data],">="&DATE(YEAR(TODAY()),1,1),tblFornos[Data],"<"&DATE(YEAR(TODAY()),2,1)) | I28: =COUNTIFS(tblFornos[Tipo],"Inspecao",tblFornos[Data],">="&DATE(YEAR(TODAY()),1,1),tblFornos[Data],"<"&DATE(YEAR(TODAY()),2,1)) | L28: =C28+E28+G28+I28
B29: Fevereiro | C29: =COUNTIFS(tblFornos[Tipo],"Operacao",tblFornos[Data],">="&DATE(YEAR(TODAY()),2,1),tblFornos[Data],"<"&DATE(YEAR(TODAY()),3,1)) | E29: =COUNTIFS(tblFornos[Tipo],"Manutencao",tblFornos[Data],">="&DATE(YEAR(TODAY()),2,1),tblFornos[Data],"<"&DATE(YEAR(TODAY()),3,1)) | G29: =COUNTIFS(tblFornos[Tipo],"Falha",tblFornos[Data],">="&DATE(YEAR(TODAY()),2,1),tblFornos[Data],"<"&DATE(YEAR(TODAY()),3,1)) | I29: =COUNTIFS(tblFornos[Tipo],"Inspecao",tblFornos[Data],">="&DATE(YEAR(TODAY()),2,1),tblFornos[Data],"<"&DATE(YEAR(TODAY()),3,1)) | L29: =C29+E29+G29+I29
B30: Marco | C30: =COUNTIFS(tblFornos[Tipo],"Operacao",tblFornos[Data],">="&DATE(YEAR(TODAY()),3,1),tblFornos[Data],"<"&DATE(YEAR(TODAY()),4,1)) | E30: =COUNTIFS(tblFornos[Tipo],"Manutencao",tblFornos[Data],">="&DATE(YEAR(TODAY()),3,1),tblFornos[Data],"<"&DATE(YEAR(TODAY()),4,1)) | G30: =COUNTIFS(tblFornos[Tipo],"Falha",tblFornos[Data],">="&DATE(YEAR(TODAY()),3,1),tblFornos[Data],"<"&DATE(YEAR(TODAY()),4,1)) | I30: =COUNTIFS(tblFornos[Tipo],"Inspecao",tblFornos[Data],">="&DATE(YEAR(TODAY()),3,1),tblFornos[Data],"<"&DATE(YEAR(TODAY()),4,1)) | L30: =C30+E30+G30+I30
B31: Abril | C31: =COUNTIFS(tblFornos[Tipo],"Operacao",tblFornos[Data],">="&DATE(YEAR(TODAY()),4,1),tblFornos[Data],"<"&DATE(YEAR(TODAY()),5,1)) | E31: =COUNTIFS(tblFornos[Tipo],"Manutencao",tblFornos[Data],">="&DATE(YEAR(TODAY()),4,1),tblFornos[Data],"<"&DATE(YEAR(TODAY()),5,1)) | G31: =COUNTIFS(tblFornos[Tipo],"Falha",tblFornos[Data],">="&DATE(YEAR(TODAY()),4,1),tblFornos[Data],"<"&DATE(YEAR(TODAY()),5,1)) | I31: =COUNTIFS(tblFornos[Tipo],"Inspecao",tblFornos[Data],">="&DATE(YEAR(TODAY()),4,1),tblFornos[Data],"<"&DATE(YEAR(TODAY()),5,1)) | L31: =C31+E31+G31+I31
B32: Maio | C32: =COUNTIFS(tblFornos[Tipo],"Operacao",tblFornos[Data],">="&DATE(YEAR(TODAY()),5,1),tblFornos[Data],"<"&DATE(YEAR(TODAY()),6,1)) | E32: =COUNTIFS(tblFornos[Tipo],"Manutencao",tblFornos[Data],">="&DATE(YEAR(TODAY()),5,1),tblFornos[Data],"<"&DATE(YEAR(TODAY()),6,1)) | G32: =COUNTIFS(tblFornos[Tipo],"Falha",tblFornos[Data],">="&DATE(YEAR(TODAY()),5,1),tblFornos[Data],"<"&DATE(YEAR(TODAY()),6,1)) | I32: =COUNTIFS(tblFornos[Tipo],"Inspecao",tblFornos[Data],">="&DATE(YEAR(TODAY()),5,1),tblFornos[Data],"<"&DATE(YEAR(TODAY()),6,1)) | L32: =C32+E32+G32+I32
B33: Junho | C33: =COUNTIFS(tblFornos[Tipo],"Operacao",tblFornos[Data],">="&DATE(YEAR(TODAY()),6,1),tblFornos[Data],"<"&DATE(YEAR(TODAY()),7,1)) | E33: =COUNTIFS(tblFornos[Tipo],"Manutencao",tblFornos[Data],">="&DATE(YEAR(TODAY()),6,1),tblFornos[Data],"<"&DATE(YEAR(TODAY()),7,1)) | G33: =COUNTIFS(tblFornos[Tipo],"Falha",tblFornos[Data],">="&DATE(YEAR(TODAY()),6,1),tblFornos[Data],"<"&DATE(YEAR(TODAY()),7,1)) | I33: =COUNTIFS(tblFornos[Tipo],"Inspecao",tblFornos[Data],">="&DATE(YEAR(TODAY()),6,1),tblFornos[Data],"<"&DATE(YEAR(TODAY()),7,1)) | L33: =C33+E33+G33+I33
B34: Julho | C34: =COUNTIFS(tblFornos[Tipo],"Operacao",tblFornos[Data],">="&DATE(YEAR(TODAY()),7,1),tblFornos[Data],"<"&DATE(YEAR(TODAY()),8,1)) | E34: =COUNTIFS(tblFornos[Tipo],"Manutencao",tblFornos[Data],">="&DATE(YEAR(TODAY()),7,1),tblFornos[Data],"<"&DATE(YEAR(TODAY()),8,1)) | G34: =COUNTIFS(tblFornos[Tipo],"Falha",tblFornos[Data],">="&DATE(YEAR(TODAY()),7,1),tblFornos[Data],"<"&DATE(YEAR(TODAY()),8,1)) | I34: =COUNTIFS(tblFornos[Tipo],"Inspecao",tblFornos[Data],">="&DATE(YEAR(TODAY()),7,1),tblFornos[Data],"<"&DATE(YEAR(TODAY()),8,1)) | L34: =C34+E34+G34+I34
B35: Agosto | C35: =COUNTIFS(tblFornos[Tipo],"Operacao",tblFornos[Data],">="&DATE(YEAR(TODAY()),8,1),tblFornos[Data],"<"&DATE(YEAR(TODAY()),9,1)) | E35: =COUNTIFS(tblFornos[Tipo],"Manutencao",tblFornos[Data],">="&DATE(YEAR(TODAY()),8,1),tblFornos[Data],"<"&DATE(YEAR(TODAY()),9,1)) | G35: =COUNTIFS(tblFornos[Tipo],"Falha",tblFornos[Data],">="&DATE(YEAR(TODAY()),8,1),tblFornos[Data],"<"&DATE(YEAR(TODAY()),9,1)) | I35: =COUNTIFS(tblFornos[Tipo],"Inspecao",tblFornos[Data],">="&DATE(YEAR(TODAY()),8,1),tblFornos[Data],"<"&DATE(YEAR(TODAY()),9,1)) | L35: =C35+E35+G35+I35
B36: Setembro | C36: =COUNTIFS(tblFornos[Tipo],"Operacao",tblFornos[Data],">="&DATE(YEAR(TODAY()),9,1),tblFornos[Data],"<"&DATE(YEAR(TODAY()),10,1)) | E36: =COUNTIFS(tblFornos[Tipo],"Manutencao",tblFornos[Data],">="&DATE(YEAR(TODAY()),9,1),tblFornos[Data],"<"&DATE(YEAR(TODAY()),10,1)) | G36: =COUNTIFS(tblFornos[Tipo],"Falha",tblFornos[Data],">="&DATE(YEAR(TODAY()),9,1),tblFornos[Data],"<"&DATE(YEAR(TODAY()),10,1)) | I36: =COUNTIFS(tblFornos[Tipo],"Inspecao",tblFornos[Data],">="&DATE(YEAR(TODAY()),9,1),tblFornos[Data],"<"&DATE(YEAR(TODAY()),10,1)) | L36: =C36+E36+G36+I36
B37: Outubro | C37: =COUNTIFS(tblFornos[Tipo],"Operacao",tblFornos[Data],">="&DATE(YEAR(TODAY()),10,1),tblFornos[Data],"<"&DATE(YEAR(TODAY()),11,1)) | E37: =COUNTIFS(tblFornos[Tipo],"Manutencao",tblFornos[Data],">="&DATE(YEAR(TODAY()),10,1),tblFornos[Data],"<"&DATE(YEAR(TODAY()),11,1)) | G37: =COUNTIFS(tblFornos[Tipo],"Falha",tblFornos[Data],">="&DATE(YEAR(TODAY()),10,1),tblFornos[Data],"<"&DATE(YEAR(TODAY()),11,1)) | I37: =COUNTIFS(tblFornos[Tipo],"Inspecao",tblFornos[Data],">="&DATE(YEAR(TODAY()),10,1),tblFornos[Data],"<"&DATE(YEAR(TODAY()),11,1)) | L37: =C37+E37+G37+I37
B38: Novembro | C38: =COUNTIFS(tblFornos[Tipo],"Operacao",tblFornos[Data],">="&DATE(YEAR(TODAY()),11,1),tblFornos[Data],"<"&DATE(YEAR(TODAY()),12,1)) | E38: =COUNTIFS(tblFornos[Tipo],"Manutencao",tblFornos[Data],">="&DATE(YEAR(TODAY()),11,1),tblFornos[Data],"<"&DATE(YEAR(TODAY()),12,1)) | G38: =COUNTIFS(tblFornos[Tipo],"Falha",tblFornos[Data],">="&DATE(YEAR(TODAY()),11,1),tblFornos[Data],"<"&DATE(YEAR(TODAY()),12,1)) | I38: =COUNTIFS(tblFornos[Tipo],"Inspecao",tblFornos[Data],">="&DATE(YEAR(TODAY()),11,1),tblFornos[Data],"<"&DATE(YEAR(TODAY()),12,1)) | L38: =C38+E38+G38+I38
B39: Dezembro | C39: =COUNTIFS(tblFornos[Tipo],"Operacao",tblFornos[Data],">="&DATE(YEAR(TODAY()),12,1),tblFornos[Data],"<"&DATE(YEAR(TODAY()),13,1)) | E39: =COUNTIFS(tblFornos[Tipo],"Manutencao",tblFornos[Data],">="&DATE(YEAR(TODAY()),12,1),tblFornos[Data],"<"&DATE(YEAR(TODAY()),13,1)) | G39: =COUNTIFS(tblFornos[Tipo],"Falha",tblFornos[Data],">="&DATE(YEAR(TODAY()),12,1),tblFornos[Data],"<"&DATE(YEAR(TODAY()),13,1)) | I39: =COUNTIFS(tblFornos[Tipo],"Inspecao",tblFornos[Data],">="&DATE(YEAR(TODAY()),12,1),tblFornos[Data],"<"&DATE(YEAR(TODAY()),13,1)) | L39: =C39+E39+G39+I39
B40: TOTAL | C40: =COUNTIFS(tblFornos[Tipo],"Operacao") | E40: =COUNTIFS(tblFornos[Tipo],"Manutencao") | G40: =COUNTIFS(tblFornos[Tipo],"Falha") | I40: =COUNTIFS(tblFornos[Tipo],"Inspecao") | L40: =COUNTA(tblFornos[ID])

Sheet Registro
B2: REGISTRO RAPIDO DE FORNOS
B4: DATA | C4: FORNO | D4: TIPO | E4: LADO | G4: REGISTRAR | J4: LIMPAR | M4: Preencha os 4 campos e clique em REGISTRAR. Sem macros: digite uma nova linha direto na tabela (via Dados/Conexoes ou edite a aba _Dados).
B5: 46151 | D5: Operacao | E5: A
B7: =IF(COUNTA(tblFornos[ID])>0,"Ultimo registro: ID "&MAX(tblFornos[ID])&" - Total na base: "&COUNTA(tblFornos[ID])&" registros","Sem registros ainda.")
B9: REGISTROS POR TIPO - Forno + Quantidade. Totais ao final.
B10: OPERACAO | E10: MANUTENCAO | H10: FALHA | K10: INSPECAO | N10: RESUMO POR FORNO
B11: Forno | C11: Qtd | E11: Forno | F11: Qtd | H11: Forno | I11: Qtd | K11: Forno | L11: Qtd | N11: Forno | O11: O / M / F / I | P11: Total | Q11: % Falha
B12: =IFERROR(_Dados!T2,"") | C12: =IFERROR(_Dados!U2,"") | E12: =IFERROR(_Dados!V2,"") | F12: =IFERROR(_Dados!W2,"") | H12: =IFERROR(_Dados!X2,"") | I12: =IFERROR(_Dados!Y2,"") | K12: =IFERROR(_Dados!Z2,"") | L12: =IFERROR(_Dados!AA2,"") | N12: =IFERROR(INDEX(tblFornos[Forno],MATCH(LARGE(IF(COUNTIF($N$11:N11,tblFornos[Forno])=0,COUNTIFS(tblFornos[Forno],tblFornos[Forno])),1),IF(COUNTIF($N$11:N11,tblFornos[Forno])=0,COUNTIFS(tblFornos[Forno],tblFornos[Forno])),0)),"") | O12: =IF(N12="","",COUNTIFS(tblFornos[Forno],N12,tblFornos[Tipo],"Operacao")&"/"&COUNTIFS(tblFornos[Forno],N12,tblFornos[Tipo],"Manutencao")&"/"&COUNTIFS(tblFornos[Forno],N12,tblFornos[Tipo],"Falha")&"/"&COUNTIFS(tblFornos[Forno],N12,tblFornos[Tipo],"Inspecao")) | P12: =IF(N12="","",COUNTIFS(tblFornos[Forno],N12)) | Q12: =IF(OR(N12="",P12=0),"",COUNTIFS(tblFornos[Forno],N12,tblFornos[Tipo],"Falha")/P12)
B13: =IFERROR(_Dados!T3,"") | C13: =IFERROR(_Dados!U3,"") | E13: =IFERROR(_Dados!V3,"") | F13: =IFERROR(_Dados!W3,"") | H13: =IFERROR(_Dados!X3,"") | I13: =IFERROR(_Dados!Y3,"") | K13: =IFERROR(_Dados!Z3,"") | L13: =IFERROR(_Dados!AA3,"") | N13: =IFERROR(INDEX(tblFornos[Forno],MATCH(LARGE(IF(COUNTIF($N$11:N12,tblFornos[Forno])=0,COUNTIFS(tblFornos[Forno],tblFornos[Forno])),1),IF(COUNTIF($N$11:N12,tblFornos[Forno])=0,COUNTIFS(tblFornos[Forno],tblFornos[Forno])),0)),"") | O13: =IF(N13="","",COUNTIFS(tblFornos[Forno],N13,tblFornos[Tipo],"Operacao")&"/"&COUNTIFS(tblFornos[Forno],N13,tblFornos[Tipo],"Manutencao")&"/"&COUNTIFS(tblFornos[Forno],N13,tblFornos[Tipo],"Falha")&"/"&COUNTIFS(tblFornos[Forno],N13,tblFornos[Tipo],"Inspecao")) | P13: =IF(N13="","",COUNTIFS(tblFornos[Forno],N13)) | Q13: =IF(OR(N13="",P13=0),"",COUNTIFS(tblFornos[Forno],N13,tblFornos[Tipo],"Falha")/P13)
B14: =IFERROR(_Dados!T4,"") | C14: =IFERROR(_Dados!U4,"") | E14: =IFERROR(_Dados!V4,"") | F14: =IFERROR(_Dados!W4,"") | H14: =IFERROR(_Dados!X4,"") | I14: =IFERROR(_Dados!Y4,"") | K14: =IFERROR(_Dados!Z4,"") | L14: =IFERROR(_Dados!AA4,"") | N14: =IFERROR(INDEX(tblFornos[Forno],MATCH(LARGE(IF(COUNTIF($N$11:N13,tblFornos[Forno])=0,COUNTIFS(tblFornos[Forno],tblFornos[Forno])),1),IF(COUNTIF($N$11:N13,tblFornos[Forno])=0,COUNTIFS(tblFornos[Forno],tblFornos[Forno])),0)),"") | O14: =IF(N14="","",COUNTIFS(tblFornos[Forno],N14,tblFornos[Tipo],"Operacao")&"/"&COUNTIFS(tblFornos[Forno],N14,tblFornos[Tipo],"Manutencao")&"/"&COUNTIFS(tblFornos[Forno],N14,tblFornos[Tipo],"Falha")&"/"&COUNTIFS(tblFornos[Forno],N14,tblFornos[Tipo],"Inspecao")) | P14: =IF(N14="","",COUNTIFS(tblFornos[Forno],N14)) | Q14: =IF(OR(N14="",P14=0),"",COUNTIFS(tblFornos[Forno],N14,tblFornos[Tipo],"Falha")/P14)
B15: =IFERROR(_Dados!T5,"") | C15: =IFERROR(_Dados!U5,"") | E15: =IFERROR(_Dados!V5,"") | F15: =IFERROR(_Dados!W5,"") | H15: =IFERROR(_Dados!X5,"") | I15: =IFERROR(_Dados!Y5,"") | K15: =IFERROR(_Dados!Z5,"") | L15: =IFERROR(_Dados!AA5,"") | N15: =IFERROR(INDEX(tblFornos[Forno],MATCH(LARGE(IF(COUNTIF($N$11:N14,tblFornos[Forno])=0,COUNTIFS(tblFornos[Forno],tblFornos[Forno])),1),IF(COUNTIF($N$11:N14,tblFornos[Forno])=0,COUNTIFS(tblFornos[Forno],tblFornos[Forno])),0)),"") | O15: =IF(N15="","",COUNTIFS(tblFornos[Forno],N15,tblFornos[Tipo],"Operacao")&"/"&COUNTIFS(tblFornos[Forno],N15,tblFornos[Tipo],"Manutencao")&"/"&COUNTIFS(tblFornos[Forno],N15,tblFornos[Tipo],"Falha")&"/"&COUNTIFS(tblFornos[Forno],N15,tblFornos[Tipo],"Inspecao")) | P15: =IF(N15="","",COUNTIFS(tblFornos[Forno],N15)) | Q15: =IF(OR(N15="",P15=0),"",COUNTIFS(tblFornos[Forno],N15,tblFornos[Tipo],"Falha")/P15)
B16: =IFERROR(_Dados!T6,"") | C16: =IFERROR(_Dados!U6,"") | E16: =IFERROR(_Dados!V6,"") | F16: =IFERROR(_Dados!W6,"") | H16: =IFERROR(_Dados!X6,"") | I16: =IFERROR(_Dados!Y6,"") | K16: =IFERROR(_Dados!Z6,"") | L16: =IFERROR(_Dados!AA6,"") | N16: =IFERROR(INDEX(tblFornos[Forno],MATCH(LARGE(IF(COUNTIF($N$11:N15,tblFornos[Forno])=0,COUNTIFS(tblFornos[Forno],tblFornos[Forno])),1),IF(COUNTIF($N$11:N15,tblFornos[Forno])=0,COUNTIFS(tblFornos[Forno],tblFornos[Forno])),0)),"") | O16: =IF(N16="","",COUNTIFS(tblFornos[Forno],N16,tblFornos[Tipo],"Operacao")&"/"&COUNTIFS(tblFornos[Forno],N16,tblFornos[Tipo],"Manutencao")&"/"&COUNTIFS(tblFornos[Forno],N16,tblFornos[Tipo],"Falha")&"/"&COUNTIFS(tblFornos[Forno],N16,tblFornos[Tipo],"Inspecao")) | P16: =IF(N16="","",COUNTIFS(tblFornos[Forno],N16)) | Q16: =IF(OR(N16="",P16=0),"",COUNTIFS(tblFornos[Forno],N16,tblFornos[Tipo],"Falha")/P16)
B17: =IFERROR(_Dados!T7,"") | C17: =IFERROR(_Dados!U7,"") | E17: =IFERROR(_Dados!V7,"") | F17: =IFERROR(_Dados!W7,"") | H17: =IFERROR(_Dados!X7,"") | I17: =IFERROR(_Dados!Y7,"") | K17: =IFERROR(_Dados!Z7,"") | L17: =IFERROR(_Dados!AA7,"") | N17: =IFERROR(INDEX(tblFornos[Forno],MATCH(LARGE(IF(COUNTIF($N$11:N16,tblFornos[Forno])=0,COUNTIFS(tblFornos[Forno],tblFornos[Forno])),1),IF(COUNTIF($N$11:N16,tblFornos[Forno])=0,COUNTIFS(tblFornos[Forno],tblFornos[Forno])),0)),"") | O17: =IF(N17="","",COUNTIFS(tblFornos[Forno],N17,tblFornos[Tipo],"Operacao")&"/"&COUNTIFS(tblFornos[Forno],N17,tblFornos[Tipo],"Manutencao")&"/"&COUNTIFS(tblFornos[Forno],N17,tblFornos[Tipo],"Falha")&"/"&COUNTIFS(tblFornos[Forno],N17,tblFornos[Tipo],"Inspecao")) | P17: =IF(N17="","",COUNTIFS(tblFornos[Forno],N17)) | Q17: =IF(OR(N17="",P17=0),"",COUNTIFS(tblFornos[Forno],N17,tblFornos[Tipo],"Falha")/P17)
B18: =IFERROR(_Dados!T8,"") | C18: =IFERROR(_Dados!U8,"") | E18: =IFERROR(_Dados!V8,"") | F18: =IFERROR(_Dados!W8,"") | H18: =IFERROR(_Dados!X8,"") | I18: =IFERROR(_Dados!Y8,"") | K18: =IFERROR(_Dados!Z8,"") | L18: =IFERROR(_Dados!AA8,"") | N18: =IFERROR(INDEX(tblFornos[Forno],MATCH(LARGE(IF(COUNTIF($N$11:N17,tblFornos[Forno])=0,COUNTIFS(tblFornos[Forno],tblFornos[Forno])),1),IF(COUNTIF($N$11:N17,tblFornos[Forno])=0,COUNTIFS(tblFornos[Forno],tblFornos[Forno])),0)),"") | O18: =IF(N18="","",COUNTIFS(tblFornos[Forno],N18,tblFornos[Tipo],"Operacao")&"/"&COUNTIFS(tblFornos[Forno],N18,tblFornos[Tipo],"Manutencao")&"/"&COUNTIFS(tblFornos[Forno],N18,tblFornos[Tipo],"Falha")&"/"&COUNTIFS(tblFornos[Forno],N18,tblFornos[Tipo],"Inspecao")) | P18: =IF(N18="","",COUNTIFS(tblFornos[Forno],N18)) | Q18: =IF(OR(N18="",P18=0),"",COUNTIFS(tblFornos[Forno],N18,tblFornos[Tipo],"Falha")/P18)
B19: =IFERROR(_Dados!T9,"") | C19: =IFERROR(_Dados!U9,"") | E19: =IFERROR(_Dados!V9,"") | F19: =IFERROR(_Dados!W9,"") | H19: =IFERROR(_Dados!X9,"") | I19: =IFERROR(_Dados!Y9,"") | K19: =IFERROR(_Dados!Z9,"") | L19: =IFERROR(_Dados!AA9,"") | N19: =IFERROR(INDEX(tblFornos[Forno],MATCH(LARGE(IF(COUNTIF($N$11:N18,tblFornos[Forno])=0,COUNTIFS(tblFornos[Forno],tblFornos[Forno])),1),IF(COUNTIF($N$11:N18,tblFornos[Forno])=0,COUNTIFS(tblFornos[Forno],tblFornos[Forno])),0)),"") | O19: =IF(N19="","",COUNTIFS(tblFornos[Forno],N19,tblFornos[Tipo],"Operacao")&"/"&COUNTIFS(tblFornos[Forno],N19,tblFornos[Tipo],"Manutencao")&"/"&COUNTIFS(tblFornos[Forno],N19,tblFornos[Tipo],"Falha")&"/"&COUNTIFS(tblFornos[Forno],N19,tblFornos[Tipo],"Inspecao")) | P19: =IF(N19="","",COUNTIFS(tblFornos[Forno],N19)) | Q19: =IF(OR(N19="",P19=0),"",COUNTIFS(tblFornos[Forno],N19,tblFornos[Tipo],"Falha")/P19)
B20: =IFERROR(_Dados!T10,"") | C20: =IFERROR(_Dados!U10,"") | E20: =IFERROR(_Dados!V10,"") | F20: =IFERROR(_Dados!W10,"") | H20: =IFERROR(_Dados!X10,"") | I20: =IFERROR(_Dados!Y10,"") | K20: =IFERROR(_Dados!Z10,"") | L20: =IFERROR(_Dados!AA10,"") | N20: =IFERROR(INDEX(tblFornos[Forno],MATCH(LARGE(IF(COUNTIF($N$11:N19,tblFornos[Forno])=0,COUNTIFS(tblFornos[Forno],tblFornos[Forno])),1),IF(COUNTIF($N$11:N19,tblFornos[Forno])=0,COUNTIFS(tblFornos[Forno],tblFornos[Forno])),0)),"") | O20: =IF(N20="","",COUNTIFS(tblFornos[Forno],N20,tblFornos[Tipo],"Operacao")&"/"&COUNTIFS(tblFornos[Forno],N20,tblFornos[Tipo],"Manutencao")&"/"&COUNTIFS(tblFornos[Forno],N20,tblFornos[Tipo],"Falha")&"/"&COUNTIFS(tblFornos[Forno],N20,tblFornos[Tipo],"Inspecao")) | P20: =IF(N20="","",COUNTIFS(tblFornos[Forno],N20)) | Q20: =IF(OR(N20="",P20=0),"",COUNTIFS(tblFornos[Forno],N20,tblFornos[Tipo],"Falha")/P20)
B21: =IFERROR(_Dados!T11,"") | C21: =IFERROR(_Dados!U11,"") | E21: =IFERROR(_Dados!V11,"") | F21: =IFERROR(_Dados!W11,"") | H21: =IFERROR(_Dados!X11,"") | I21: =IFERROR(_Dados!Y11,"") | K21: =IFERROR(_Dados!Z11,"") | L21: =IFERROR(_Dados!AA11,"") | N21: =IFERROR(INDEX(tblFornos[Forno],MATCH(LARGE(IF(COUNTIF($N$11:N20,tblFornos[Forno])=0,COUNTIFS(tblFornos[Forno],tblFornos[Forno])),1),IF(COUNTIF($N$11:N20,tblFornos[Forno])=0,COUNTIFS(tblFornos[Forno],tblFornos[Forno])),0)),"") | O21: =IF(N21="","",COUNTIFS(tblFornos[Forno],N21,tblFornos[Tipo],"Operacao")&"/"&COUNTIFS(tblFornos[Forno],N21,tblFornos[Tipo],"Manutencao")&"/"&COUNTIFS(tblFornos[Forno],N21,tblFornos[Tipo],"Falha")&"/"&COUNTIFS(tblFornos[Forno],N21,tblFornos[Tipo],"Inspecao")) | P21: =IF(N21="","",COUNTIFS(tblFornos[Forno],N21)) | Q21: =IF(OR(N21="",P21=0),"",COUNTIFS(tblFornos[Forno],N21,tblFornos[Tipo],"Falha")/P21)
B22: =IFERROR(_Dados!T12,"") | C22: =IFERROR(_Dados!U12,"") | E22: =IFERROR(_Dados!V12,"") | F22: =IFERROR(_Dados!W12,"") | H22: =IFERROR(_Dados!X12,"") | I22: =IFERROR(_Dados!Y12,"") | K22: =IFERROR(_Dados!Z12,"") | L22: =IFERROR(_Dados!AA12,"") | N22: =IFERROR(INDEX(tblFornos[Forno],MATCH(LARGE(IF(COUNTIF($N$11:N21,tblFornos[Forno])=0,COUNTIFS(tblFornos[Forno],tblFornos[Forno])),1),IF(COUNTIF($N$11:N21,tblFornos[Forno])=0,COUNTIFS(tblFornos[Forno],tblFornos[Forno])),0)),"") | O22: =IF(N22="","",COUNTIFS(tblFornos[Forno],N22,tblFornos[Tipo],"Operacao")&"/"&COUNTIFS(tblFornos[Forno],N22,tblFornos[Tipo],"Manutencao")&"/"&COUNTIFS(tblFornos[Forno],N22,tblFornos[Tipo],"Falha")&"/"&COUNTIFS(tblFornos[Forno],N22,tblFornos[Tipo],"Inspecao")) | P22: =IF(N22="","",COUNTIFS(tblFornos[Forno],N22)) | Q22: =IF(OR(N22="",P22=0),"",COUNTIFS(tblFornos[Forno],N22,tblFornos[Tipo],"Falha")/P22)
B23: =IFERROR(_Dados!T13,"") | C23: =IFERROR(_Dados!U13,"") | E23: =IFERROR(_Dados!V13,"") | F23: =IFERROR(_Dados!W13,"") | H23: =IFERROR(_Dados!X13,"") | I23: =IFERROR(_Dados!Y13,"") | K23: =IFERROR(_Dados!Z13,"") | L23: =IFERROR(_Dados!AA13,"") | N23: =IFERROR(INDEX(tblFornos[Forno],MATCH(LARGE(IF(COUNTIF($N$11:N22,tblFornos[Forno])=0,COUNTIFS(tblFornos[Forno],tblFornos[Forno])),1),IF(COUNTIF($N$11:N22,tblFornos[Forno])=0,COUNTIFS(tblFornos[Forno],tblFornos[Forno])),0)),"") | O23: =IF(N23="","",COUNTIFS(tblFornos[Forno],N23,tblFornos[Tipo],"Operacao")&"/"&COUNTIFS(tblFornos[Forno],N23,tblFornos[Tipo],"Manutencao")&"/"&COUNTIFS(tblFornos[Forno],N23,tblFornos[Tipo],"Falha")&"/"&COUNTIFS(tblFornos[Forno],N23,tblFornos[Tipo],"Inspecao")) | P23: =IF(N23="","",COUNTIFS(tblFornos[Forno],N23)) | Q23: =IF(OR(N23="",P23=0),"",COUNTIFS(tblFornos[Forno],N23,tblFornos[Tipo],"Falha")/P23)
... B31: =IFERROR(_Dados!T21,"") | C31: =IFERROR(_Dados!U21,"") | E31: =IFERROR(_Dados!V21,"") | F31: =IFERROR(_Dados!W21,"") | H31: =IFERROR(_Dados!X21,"") | I31: =IFERROR(_Dados!Y21,"") | K31: =IFERROR(_Dados!Z21,"") | L31: =IFERROR(_Dados!AA21,"") | N31: =IFERROR(INDEX(tblFornos[Forno],MATCH(LARGE(IF(COUNTIF($N$11:N30,tblFornos[Forno])=0,COUNTIFS(tblFornos[Forno],tblFornos[Forno])),1),IF(COUNTIF($N$11:N30,tblFornos[Forno])=0,COUNTIFS(tblFornos[Forno],tblFornos[Forno])),0)),"") | O31: =IF(N31="","",COUNTIFS(tblFornos[Forno],N31,tblFornos[Tipo],"Operacao")&"/"&COUNTIFS(tblFornos[Forno],N31,tblFornos[Tipo],"Manutencao")&"/"&COUNTIFS(tblFornos[Forno],N31,tblFornos[Tipo],"Falha")&"/"&COUNTIFS(tblFornos[Forno],N31,tblFornos[Tipo],"Inspecao")) | P31: =IF(N31="","",COUNTIFS(tblFornos[Forno],N31)) | Q31: =IF(OR(N31="",P31=0),"",COUNTIFS(tblFornos[Forno],N31,tblFornos[Tipo],"Falha")/P31)
B32: TOTAL | C32: =COUNTIFS(tblFornos[Tipo],"Operacao") | E32: TOTAL | F32: =COUNTIFS(tblFornos[Tipo],"Manutencao") | H32: TOTAL | I32: =COUNTIFS(tblFornos[Tipo],"Falha") | K32: TOTAL | L32: =COUNTIFS(tblFornos[Tipo],"Inspecao") | N32: =IFERROR(INDEX(tblFornos[Forno],MATCH(LARGE(IF(COUNTIF($N$11:N31,tblFornos[Forno])=0,COUNTIFS(tblFornos[Forno],tblFornos[Forno])),1),IF(COUNTIF($N$11:N31,tblFornos[Forno])=0,COUNTIFS(tblFornos[Forno],tblFornos[Forno])),0)),"") | O32: =IF(N32="","",COUNTIFS(tblFornos[Forno],N32,tblFornos[Tipo],"Operacao")&"/"&COUNTIFS(tblFornos[Forno],N32,tblFornos[Tipo],"Manutencao")&"/"&COUNTIFS(tblFornos[Forno],N32,tblFornos[Tipo],"Falha")&"/"&COUNTIFS(tblFornos[Forno],N32,tblFornos[Tipo],"Inspecao")) | P32: =IF(N32="","",COUNTIFS(tblFornos[Forno],N32)) | Q32: =IF(OR(N32="",P32=0),"",COUNTIFS(tblFornos[Forno],N32,tblFornos[Tipo],"Falha")/P32)
N33: =IFERROR(INDEX(tblFornos[Forno],MATCH(LARGE(IF(COUNTIF($N$11:N32,tblFornos[Forno])=0,COUNTIFS(tblFornos[Forno],tblFornos[Forno])),1),IF(COUNTIF($N$11:N32,tblFornos[Forno])=0,COUNTIFS(tblFornos[Forno],tblFornos[Forno])),0)),"") | O33: =IF(N33="","",COUNTIFS(tblFornos[Forno],N33,tblFornos[Tipo],"Operacao")&"/"&COUNTIFS(tblFornos[Forno],N33,tblFornos[Tipo],"Manutencao")&"/"&COUNTIFS(tblFornos[Forno],N33,tblFornos[Tipo],"Falha")&"/"&COUNTIFS(tblFornos[Forno],N33,tblFornos[Tipo],"Inspecao")) | P33: =IF(N33="","",COUNTIFS(tblFornos[Forno],N33)) | Q33: =IF(OR(N33="",P33=0),"",COUNTIFS(tblFornos[Forno],N33,tblFornos[Tipo],"Falha")/P33)
N34: =IFERROR(INDEX(tblFornos[Forno],MATCH(LARGE(IF(COUNTIF($N$11:N33,tblFornos[Forno])=0,COUNTIFS(tblFornos[Forno],tblFornos[Forno])),1),IF(COUNTIF($N$11:N33,tblFornos[Forno])=0,COUNTIFS(tblFornos[Forno],tblFornos[Forno])),0)),"") | O34: =IF(N34="","",COUNTIFS(tblFornos[Forno],N34,tblFornos[Tipo],"Operacao")&"/"&COUNTIFS(tblFornos[Forno],N34,tblFornos[Tipo],"Manutencao")&"/"&COUNTIFS(tblFornos[Forno],N34,tblFornos[Tipo],"Falha")&"/"&COUNTIFS(tblFornos[Forno],N34,tblFornos[Tipo],"Inspecao")) | P34: =IF(N34="","",COUNTIFS(tblFornos[Forno],N34)) | Q34: =IF(OR(N34="",P34=0),"",COUNTIFS(tblFornos[Forno],N34,tblFornos[Tipo],"Falha")/P34)
N35: =IFERROR(INDEX(tblFornos[Forno],MATCH(LARGE(IF(COUNTIF($N$11:N34,tblFornos[Forno])=0,COUNTIFS(tblFornos[Forno],tblFornos[Forno])),1),IF(COUNTIF($N$11:N34,tblFornos[Forno])=0,COUNTIFS(tblFornos[Forno],tblFornos[Forno])),0)),"") | O35: =IF(N35="","",COUNTIFS(tblFornos[Forno],N35,tblFornos[Tipo],"Operacao")&"/"&COUNTIFS(tblFornos[Forno],N35,tblFornos[Tipo],"Manutencao")&"/"&COUNTIFS(tblFornos[Forno],N35,tblFornos[Tipo],"Falha")&"/"&COUNTIFS(tblFornos[Forno],N35,tblFornos[Tipo],"Inspecao")) | P35: =IF(N35="","",COUNTIFS(tblFornos[Forno],N35)) | Q35: =IF(OR(N35="",P35=0),"",COUNTIFS(tblFornos[Forno],N35,tblFornos[Tipo],"Falha")/P35)
N36: =IFERROR(INDEX(tblFornos[Forno],MATCH(LARGE(IF(COUNTIF($N$11:N35,tblFornos[Forno])=0,COUNTIFS(tblFornos[Forno],tblFornos[Forno])),1),IF(COUNTIF($N$11:N35,tblFornos[Forno])=0,COUNTIFS(tblFornos[Forno],tblFornos[Forno])),0)),"") | O36: =IF(N36="","",COUNTIFS(tblFornos[Forno],N36,tblFornos[Tipo],"Operacao")&"/"&COUNTIFS(tblFornos[Forno],N36,tblFornos[Tipo],"Manutencao")&"/"&COUNTIFS(tblFornos[Forno],N36,tblFornos[Tipo],"Falha")&"/"&COUNTIFS(tblFornos[Forno],N36,tblFornos[Tipo],"Inspecao")) | P36: =IF(N36="","",COUNTIFS(tblFornos[Forno],N36)) | Q36: =IF(OR(N36="",P36=0),"",COUNTIFS(tblFornos[Forno],N36,tblFornos[Tipo],"Falha")/P36)
N37: TOTAL GERAL | O37: =COUNTIFS(tblFornos[Tipo],"Operacao")&"/"&COUNTIFS(tblFornos[Tipo],"Manutencao")&"/"&COUNTIFS(tblFornos[Tipo],"Falha")&"/"&COUNTIFS(tblFornos[Tipo],"Inspecao") | P37: =COUNTA(tblFornos[ID]) | Q37: =IF(P37=0,"",COUNTIFS(tblFornos[Tipo],"Falha")/P37)

Sheet Filtros
B2: FILTROS E ANALISE DETALHADA
B4: Data inicial | C4: Data final | D4: Forno | E4: Tipo | F4: Lado | G4: Dia | H4: Mes | I4: Ano | J4: LIMPAR
B7: Busca livre | J7: (forno, tipo, lado)
B9: =" Resultados encontrados: "&SUMPRODUCT(--(_Dados!AC2:AC201<>""))&" registros"
B11: ID | C11: Data | D11: Forno | E11: Tipo | F11: Lado | G11: Dia | H11: Mes | I11: Ano | J11: Semana
B12: =IFERROR(_Dados!AC2,"") | C12: =IFERROR(_Dados!AD2,"") | D12: =IFERROR(_Dados!AE2,"") | E12: =IFERROR(_Dados!AF2,"") | F12: =IFERROR(_Dados!AG2,"") | G12: =IF(_Dados!AD2="","",DAY(_Dados!AD2)) | H12: =IF(_Dados!AD2="","",MONTH(_Dados!AD2)) | I12: =IF(_Dados!AD2="","",YEAR(_Dados!AD2)) | J12: =IF(_Dados!AD2="","",WEEKNUM(_Dados!AD2))
B13: =IFERROR(_Dados!AC3,"") | C13: =IFERROR(_Dados!AD3,"") | D13: =IFERROR(_Dados!AE3,"") | E13: =IFERROR(_Dados!AF3,"") | F13: =IFERROR(_Dados!AG3,"") | G13: =IF(_Dados!AD3="","",DAY(_Dados!AD3)) | H13: =IF(_Dados!AD3="","",MONTH(_Dados!AD3)) | I13: =IF(_Dados!AD3="","",YEAR(_Dados!AD3)) | J13: =IF(_Dados!AD3="","",WEEKNUM(_Dados!AD3))
B14: =IFERROR(_Dados!AC4,"") | C14: =IFERROR(_Dados!AD4,"") | D14: =IFERROR(_Dados!AE4,"") | E14: =IFERROR(_Dados!AF4,"") | F14: =IFERROR(_Dados!AG4,"") | G14: =IF(_Dados!AD4="","",DAY(_Dados!AD4)) | H14: =IF(_Dados!AD4="","",MONTH(_Dados!AD4)) | I14: =IF(_Dados!AD4="","",YEAR(_Dados!AD4)) | J14: =IF(_Dados!AD4="","",WEEKNUM(_Dados!AD4))
B15: =IFERROR(_Dados!AC5,"") | C15: =IFERROR(_Dados!AD5,"") | D15: =IFERROR(_Dados!AE5,"") | E15: =IFERROR(_Dados!AF5,"") | F15: =IFERROR(_Dados!AG5,"") | G15: =IF(_Dados!AD5="","",DAY(_Dados!AD5)) | H15: =IF(_Dados!AD5="","",MONTH(_Dados!AD5)) | I15: =IF(_Dados!AD5="","",YEAR(_Dados!AD5)) | J15: =IF(_Dados!AD5="","",WEEKNUM(_Dados!AD5))
B16: =IFERROR(_Dados!AC6,"") | C16: =IFERROR(_Dados!AD6,"") | D16: =IFERROR(_Dados!AE6,"") | E16: =IFERROR(_Dados!AF6,"") | F16: =IFERROR(_Dados!AG6,"") | G16: =IF(_Dados!AD6="","",DAY(_Dados!AD6)) | H16: =IF(_Dados!AD6="","",MONTH(_Dados!AD6)) | I16: =IF(_Dados!AD6="","",YEAR(_Dados!AD6)) | J16: =IF(_Dados!AD6="","",WEEKNUM(_Dados!AD6))
B17: =IFERROR(_Dados!AC7,"") | C17: =IFERROR(_Dados!AD7,"") | D17: =IFERROR(_Dados!AE7,"") | E17: =IFERROR(_Dados!AF7,"") | F17: =IFERROR(_Dados!AG7,"") | G17: =IF(_Dados!AD7="","",DAY(_Dados!AD7)) | H17: =IF(_Dados!AD7="","",MONTH(_Dados!AD7)) | I17: =IF(_Dados!AD7="","",YEAR(_Dados!AD7)) | J17: =IF(_Dados!AD7="","",WEEKNUM(_Dados!AD7))
B18: =IFERROR(_Dados!AC8,"") | C18: =IFERROR(_Dados!AD8,"") | D18: =IFERROR(_Dados!AE8,"") | E18: =IFERROR(_Dados!AF8,"") | F18: =IFERROR(_Dados!AG8,"") | G18: =IF(_Dados!AD8="","",DAY(_Dados!AD8)) | H18: =IF(_Dados!AD8="","",MONTH(_Dados!AD8)) | I18: =IF(_Dados!AD8="","",YEAR(_Dados!AD8)) | J18: =IF(_Dados!AD8="","",WEEKNUM(_Dados!AD8))
B19: =IFERROR(_Dados!AC9,"") | C19: =IFERROR(_Dados!AD9,"") | D19: =IFERROR(_Dados!AE9,"") | E19: =IFERROR(_Dados!AF9,"") | F19: =IFERROR(_Dados!AG9,"") | G19: =IF(_Dados!AD9="","",DAY(_Dados!AD9)) | H19: =IF(_Dados!AD9="","",MONTH(_Dados!AD9)) | I19: =IF(_Dados!AD9="","",YEAR(_Dados!AD9)) | J19: =IF(_Dados!AD9="","",WEEKNUM(_Dados!AD9))
B20: =IFERROR(_Dados!AC10,"") | C20: =IFERROR(_Dados!AD10,"") | D20: =IFERROR(_Dados!AE10,"") | E20: =IFERROR(_Dados!AF10,"") | F20: =IFERROR(_Dados!AG10,"") | G20: =IF(_Dados!AD10="","",DAY(_Dados!AD10)) | H20: =IF(_Dados!AD10="","",MONTH(_Dados!AD10)) | I20: =IF(_Dados!AD10="","",YEAR(_Dados!AD10)) | J20: =IF(_Dados!AD10="","",WEEKNUM(_Dados!AD10))
B21: =IFERROR(_Dados!AC11,"") | C21: =IFERROR(_Dados!AD11,"") | D21: =IFERROR(_Dados!AE11,"") | E21: =IFERROR(_Dados!AF11,"") | F21: =IFERROR(_Dados!AG11,"") | G21: =IF(_Dados!AD11="","",DAY(_Dados!AD11)) | H21: =IF(_Dados!AD11="","",MONTH(_Dados!AD11)) | I21: =IF(_Dados!AD11="","",YEAR(_Dados!AD11)) | J21: =IF(_Dados!AD11="","",WEEKNUM(_Dados!AD11))
B22: =IFERROR(_Dados!AC12,"") | C22: =IFERROR(_Dados!AD12,"") | D22: =IFERROR(_Dados!AE12,"") | E22: =IFERROR(_Dados!AF12,"") | F22: =IFERROR(_Dados!AG12,"") | G22: =IF(_Dados!AD12="","",DAY(_Dados!AD12)) | H22: =IF(_Dados!AD12="","",MONTH(_Dados!AD12)) | I22: =IF(_Dados!AD12="","",YEAR(_Dados!AD12)) | J22: =IF(_Dados!AD12="","",WEEKNUM(_Dados!AD12))
B23: =IFERROR(_Dados!AC13,"") | C23: =IFERROR(_Dados!AD13,"") | D23: =IFERROR(_Dados!AE13,"") | E23: =IFERROR(_Dados!AF13,"") | F23: =IFERROR(_Dados!AG13,"") | G23: =IF(_Dados!AD13="","",DAY(_Dados!AD13)) | H23: =IF(_Dados!AD13="","",MONTH(_Dados!AD13)) | I23: =IF(_Dados!AD13="","",YEAR(_Dados!AD13)) | J23: =IF(_Dados!AD13="","",WEEKNUM(_Dados!AD13))
... B161: =IFERROR(_Dados!AC151,"") | C161: =IFERROR(_Dados!AD151,"") | D161: =IFERROR(_Dados!AE151,"") | E161: =IFERROR(_Dados!AF151,"") | F161: =IFERROR(_Dados!AG151,"") | G161: =IF(_Dados!AD151="","",DAY(_Dados!AD151)) | H161: =IF(_Dados!AD151="","",MONTH(_Dados!AD151)) | I161: =IF(_Dados!AD151="","",YEAR(_Dados!AD151)) | J161: =IF(_Dados!AD151="","",WEEKNUM(_Dados!AD151))

Sheet _Dados
A1: ID | B1: Data | C1: Forno | D1: Tipo | E1: Lado | G1: Tipos | H1: Lados | J1: Mes | K1: MesNum | L1: Qtd | N1: Dia | O1: Qtd | Q1: Tipo | R1: Qtd | T1: Forno_Operacao | U1: Qtd_Operacao | V1: Forno_Manutencao | W1: Qtd_Manutencao | X1: Forno_Falha | Y1: Qtd_Falha | Z1: Forno_Inspecao | AA1: Qtd_Inspecao | AB1: passa | AC1: fID | AD1: fData | AE1: fForno | AF1: fTipo | AG1: fLado
A2: 1 | B2: 46027 | C2: 101 | D2: Operacao | E2: A | G2: Operacao | H2: A | J2: Jan | K2: 1 | L2: =COUNTIFS(tblFornos[Data],">="&DATE(YEAR(TODAY()),1,1),tblFornos[Data],"<"&DATE(YEAR(TODAY()),2,1)) | N2: =IFERROR(INDEX(tblFornos[Data],MATCH(LARGE(IF(COUNTIF($N$1:N1,tblFornos[Data])=0,COUNTIFS(tblFornos[Data],tblFornos[Data])),1),IF(COUNTIF($N$1:N1,tblFornos[Data])=0,COUNTIFS(tblFornos[Data],tblFornos[Data])),0)),"") | O2: =IF(N2="","",COUNTIFS(tblFornos[Data],N2)) | Q2: Operacao | R2: =COUNTIFS(tblFornos[Tipo],"Operacao") | T2: =IFERROR(INDEX(tblFornos[Forno],MATCH(LARGE(IF((tblFornos[Tipo]="Operacao")*(COUNTIF($T$1:T1,tblFornos[Forno])=0),COUNTIFS(tblFornos[Forno],tblFornos[Forno],tblFornos[Tipo],"Operacao")),1),IF((tblFornos[Tipo]="Operacao")*(COUNTIF($T$1:T1,tblFornos[Forno])=0),COUNTIFS(tblFornos[Forno],tblFornos[Forno],tblFornos[Tipo],"Operacao")),0)),"") | U2: =IF(T2="","",COUNTIFS(tblFornos[Forno],T2,tblFornos[Tipo],"Operacao")) | V2: =IFERROR(INDEX(tblFornos[Forno],MATCH(LARGE(IF((tblFornos[Tipo]="Manutencao")*(COUNTIF($V$1:V1,tblFornos[Forno])=0),COUNTIFS(tblFornos[Forno],tblFornos[Forno],tblFornos[Tipo],"Manutencao")),1),IF((tblFornos[Tipo]="Manutencao")*(COUNTIF($V$1:V1,tblFornos[Forno])=0),COUNTIFS(tblFornos[Forno],tblFornos[Forno],tblFornos[Tipo],"Manutencao")),0)),"") | W2: =IF(V2="","",COUNTIFS(tblFornos[Forno],V2,tblFornos[Tipo],"Manutencao")) | X2: =IFERROR(INDEX(tblFornos[Forno],MATCH(LARGE(IF((tblFornos[Tipo]="Falha")*(COUNTIF($X$1:X1,tblFornos[Forno])=0),COUNTIFS(tblFornos[Forno],tblFornos[Forno],tblFornos[Tipo],"Falha")),1),IF((tblFornos[Tipo]="Falha")*(COUNTIF($X$1:X1,tblFornos[Forno])=0),COUNTIFS(tblFornos[Forno],tblFornos[Forno],tblFornos[Tipo],"Falha")),0)),"") | Y2: =IF(X2="","",COUNTIFS(tblFornos[Forno],X2,tblFornos[Tipo],"Falha")) | Z2: =IFERROR(INDEX(tblFornos[Forno],MATCH(LARGE(IF((tblFornos[Tipo]="Inspecao")*(COUNTIF($Z$1:Z1,tblFornos[Forno])=0),COUNTIFS(tblFornos[Forno],tblFornos[Forno],tblFornos[Tipo],"Inspecao")),1),IF((tblFornos[Tipo]="Inspecao")*(COUNTIF($Z$1:Z1,tblFornos[Forno])=0),COUNTIFS(tblFornos[Forno],tblFornos[Forno],tblFornos[Tipo],"Inspecao")),0)),"") | AA2: =IF(Z2="","",COUNTIFS(tblFornos[Forno],Z2,tblFornos[Tipo],"Inspecao")) | AB2: =IF(ROW()-1>ROWS(tblFornos[ID]),0,IF(AND(OR(Filtros!$B$5="",INDEX(tblFornos[Data],ROW()-1)>=Filtros!$B$5),OR(Filtros!$C$5="",INDEX(tblFornos[Data],ROW()-1)<=Filtros!$C$5),OR(Filtros!$D$5="",INDEX(tblFornos[Forno],ROW()-1)=Filtros!$D$5),OR(Filtros!$E$5="",INDEX(tblFornos[Tipo],ROW()-1)=Filtros!$E$5),OR(Filtros!$F$5="",INDEX(tblFornos[Lado],ROW()-1)=Filtros!$F$5),OR(Filtros!$G$5="",DAY(INDEX(tblFornos[Data],ROW()-1))=Filtros!$G$5),OR(Filtros!$H$5="",MONTH(INDEX(tblFornos[Data],ROW()-1))=Filtros!$H$5),OR(Filtros!$I$5="",YEAR(INDEX(tblFornos[Data],ROW()-1))=Filtros!$I$5),OR(Filtros!$C$7="",ISNUMBER(SEARCH(Filtros!$C$7,INDEX(tblFornos[Forno],ROW()-1)&" "&INDEX(tblFornos[Tipo],ROW()-1)&" "&INDEX(tblFornos[Lado],ROW()-1)&" "&TEXT(INDEX(tblFornos[Data],ROW()-1),"dd/mm/yyyy"))))),1,0)) | AC2: =IFERROR(INDEX(tblFornos[ID],AGGREGATE(15,6,(ROW($AB$2:$AB$201)-1)/($AB$2:$AB$201=1),ROWS($AC$2:AC2))),"") | AD2: =IF($AC2="","",INDEX(tblFornos[Data],MATCH($AC2,tblFornos[ID],0))) | AE2: =IF($AC2="","",INDEX(tblFornos[Forno],MATCH($AC2,tblFornos[ID],0))) | AF2: =IF($AC2="","",INDEX(tblFornos[Tipo],MATCH($AC2,tblFornos[ID],0))) | AG2: =IF($AC2="","",INDEX(tblFornos[Lado],MATCH($AC2,tblFornos[ID],0)))
A3: 2 | B3: 46027 | C3: 102 | D3: Manutencao | E3: B | G3: Manutencao | H3: B | J3: Fev | K3: 2 | L3: =COUNTIFS(tblFornos[Data],">="&DATE(YEAR(TODAY()),2,1),tblFornos[Data],"<"&DATE(YEAR(TODAY()),3,1)) | N3: =IFERROR(INDEX(tblFornos[Data],MATCH(LARGE(IF(COUNTIF($N$1:N2,tblFornos[Data])=0,COUNTIFS(tblFornos[Data],tblFornos[Data])),1),IF(COUNTIF($N$1:N2,tblFornos[Data])=0,COUNTIFS(tblFornos[Data],tblFornos[Data])),0)),"") | O3: =IF(N3="","",COUNTIFS(tblFornos[Data],N3)) | Q3: Manutencao | R3: =COUNTIFS(tblFornos[Tipo],"Manutencao") | T3: =IFERROR(INDEX(tblFornos[Forno],MATCH(LARGE(IF((tblFornos[Tipo]="Operacao")*(COUNTIF($T$1:T2,tblFornos[Forno])=0),COUNTIFS(tblFornos[Forno],tblFornos[Forno],tblFornos[Tipo],"Operacao")),1),IF((tblFornos[Tipo]="Operacao")*(COUNTIF($T$1:T2,tblFornos[Forno])=0),COUNTIFS(tblFornos[Forno],tblFornos[Forno],tblFornos[Tipo],"Operacao")),0)),"") | U3: =IF(T3="","",COUNTIFS(tblFornos[Forno],T3,tblFornos[Tipo],"Operacao")) | V3: =IFERROR(INDEX(tblFornos[Forno],MATCH(LARGE(IF((tblFornos[Tipo]="Manutencao")*(COUNTIF($V$1:V2,tblFornos[Forno])=0),COUNTIFS(tblFornos[Forno],tblFornos[Forno],tblFornos[Tipo],"Manutencao")),1),IF((tblFornos[Tipo]="Manutencao")*(COUNTIF($V$1:V2,tblFornos[Forno])=0),COUNTIFS(tblFornos[Forno],tblFornos[Forno],tblFornos[Tipo],"Manutencao")),0)),"") | W3: =IF(V3="","",COUNTIFS(tblFornos[Forno],V3,tblFornos[Tipo],"Manutencao")) | X3: =IFERROR(INDEX(tblFornos[Forno],MATCH(LARGE(IF((tblFornos[Tipo]="Falha")*(COUNTIF($X$1:X2,tblFornos[Forno])=0),COUNTIFS(tblFornos[Forno],tblFornos[Forno],tblFornos[Tipo],"Falha")),1),IF((tblFornos[Tipo]="Falha")*(COUNTIF($X$1:X2,tblFornos[Forno])=0),COUNTIFS(tblFornos[Forno],tblFornos[Forno],tblFornos[Tipo],"Falha")),0)),"") | Y3: =IF(X3="","",COUNTIFS(tblFornos[Forno],X3,tblFornos[Tipo],"Falha")) | Z3: =IFERROR(INDEX(tblFornos[Forno],MATCH(LARGE(IF((tblFornos[Tipo]="Inspecao")*(COUNTIF($Z$1:Z2,tblFornos[Forno])=0),COUNTIFS(tblFornos[Forno],tblFornos[Forno],tblFornos[Tipo],"Inspecao")),1),IF((tblFornos[Tipo]="Inspecao")*(COUNTIF($Z$1:Z2,tblFornos[Forno])=0),COUNTIFS(tblFornos[Forno],tblFornos[Forno],tblFornos[Tipo],"Inspecao")),0)),"") | AA3: =IF(Z3="","",COUNTIFS(tblFornos[Forno],Z3,tblFornos[Tipo],"Inspecao")) | AB3: =IF(ROW()-1>ROWS(tblFornos[ID]),0,IF(AND(OR(Filtros!$B$5="",INDEX(tblFornos[Data],ROW()-1)>=Filtros!$B$5),OR(Filtros!$C$5="",INDEX(tblFornos[Data],ROW()-1)<=Filtros!$C$5),OR(Filtros!$D$5="",INDEX(tblFornos[Forno],ROW()-1)=Filtros!$D$5),OR(Filtros!$E$5="",INDEX(tblFornos[Tipo],ROW()-1)=Filtros!$E$5),OR(Filtros!$F$5="",INDEX(tblFornos[Lado],ROW()-1)=Filtros!$F$5),OR(Filtros!$G$5="",DAY(INDEX(tblFornos[Data],ROW()-1))=Filtros!$G$5),OR(Filtros!$H$5="",MONTH(INDEX(tblFornos[Data],ROW()-1))=Filtros!$H$5),OR(Filtros!$I$5="",YEAR(INDEX(tblFornos[Data],ROW()-1))=Filtros!$I$5),OR(Filtros!$C$7="",ISNUMBER(SEARCH(Filtros!$C$7,INDEX(tblFornos[Forno],ROW()-1)&" "&INDEX(tblFornos[Tipo],ROW()-1)&" "&INDEX(tblFornos[Lado],ROW()-1)&" "&TEXT(INDEX(tblFornos[Data],ROW()-1),"dd/mm/yyyy"))))),1,0)) | AC3: =IFERROR(INDEX(tblFornos[ID],AGGREGATE(15,6,(ROW($AB$2:$AB$201)-1)/($AB$2:$AB$201=1),ROWS($AC$2:AC3))),"") | AD3: =IF($AC3="","",INDEX(tblFornos[Data],MATCH($AC3,tblFornos[ID],0))) | AE3: =IF($AC3="","",INDEX(tblFornos[Forno],MATCH($AC3,tblFornos[ID],0))) | AF3: =IF($AC3="","",INDEX(tblFornos[Tipo],MATCH($AC3,tblFornos[ID],0))) | AG3: =IF($AC3="","",INDEX(tblFornos[Lado],MATCH($AC3,tblFornos[ID],0)))
A4: 3 | B4: 46028 | C4: 101 | D4: Falha | E4: A | G4: Falha | J4: Mar | K4: 3 | L4: =COUNTIFS(tblFornos[Data],">="&DATE(YEAR(TODAY()),3,1),tblFornos[Data],"<"&DATE(YEAR(TODAY()),4,1)) | N4: =IFERROR(INDEX(tblFornos[Data],MATCH(LARGE(IF(COUNTIF($N$1:N3,tblFornos[Data])=0,COUNTIFS(tblFornos[Data],tblFornos[Data])),1),IF(COUNTIF($N$1:N3,tblFornos[Data])=0,COUNTIFS(tblFornos[Data],tblFornos[Data])),0)),"") | O4: =IF(N4="","",COUNTIFS(tblFornos[Data],N4)) | Q4: Falha | R4: =COUNTIFS(tblFornos[Tipo],"Falha") | T4: =IFERROR(INDEX(tblFornos[Forno],MATCH(LARGE(IF((tblFornos[Tipo]="Operacao")*(COUNTIF($T$1:T3,tblFornos[Forno])=0),COUNTIFS(tblFornos[Forno],tblFornos[Forno],tblFornos[Tipo],"Operacao")),1),IF((tblFornos[Tipo]="Operacao")*(COUNTIF($T$1:T3,tblFornos[Forno])=0),COUNTIFS(tblFornos[Forno],tblFornos[Forno],tblFornos[Tipo],"Operacao")),0)),"") | U4: =IF(T4="","",COUNTIFS(tblFornos[Forno],T4,tblFornos[Tipo],"Operacao")) | V4: =IFERROR(INDEX(tblFornos[Forno],MATCH(LARGE(IF((tblFornos[Tipo]="Manutencao")*(COUNTIF($V$1:V3,tblFornos[Forno])=0),COUNTIFS(tblFornos[Forno],tblFornos[Forno],tblFornos[Tipo],"Manutencao")),1),IF((tblFornos[Tipo]="Manutencao")*(COUNTIF($V$1:V3,tblFornos[Forno])=0),COUNTIFS(tblFornos[Forno],tblFornos[Forno],tblFornos[Tipo],"Manutencao")),0)),"") | W4: =IF(V4="","",COUNTIFS(tblFornos[Forno],V4,tblFornos[Tipo],"Manutencao")) | X4: =IFERROR(INDEX(tblFornos[Forno],MATCH(LARGE(IF((tblFornos[Tipo]="Falha")*(COUNTIF($X$1:X3,tblFornos[Forno])=0),COUNTIFS(tblFornos[Forno],tblFornos[Forno],tblFornos[Tipo],"Falha")),1),IF((tblFornos[Tipo]="Falha")*(COUNTIF($X$1:X3,tblFornos[Forno])=0),COUNTIFS(tblFornos[Forno],tblFornos[Forno],tblFornos[Tipo],"Falha")),0)),"") | Y4: =IF(X4="","",COUNTIFS(tblFornos[Forno],X4,tblFornos[Tipo],"Falha")) | Z4: =IFERROR(INDEX(tblFornos[Forno],MATCH(LARGE(IF((tblFornos[Tipo]="Inspecao")*(COUNTIF($Z$1:Z3,tblFornos[Forno])=0),COUNTIFS(tblFornos[Forno],tblFornos[Forno],tblFornos[Tipo],"Inspecao")),1),IF((tblFornos[Tipo]="Inspecao")*(COUNTIF($Z$1:Z3,tblFornos[Forno])=0),COUNTIFS(tblFornos[Forno],tblFornos[Forno],tblFornos[Tipo],"Inspecao")),0)),"") | AA4: =IF(Z4="","",COUNTIFS(tblFornos[Forno],Z4,tblFornos[Tipo],"Inspecao")) | AB4: =IF(ROW()-1>ROWS(tblFornos[ID]),0,IF(AND(OR(Filtros!$B$5="",INDEX(tblFornos[Data],ROW()-1)>=Filtros!$B$5),OR(Filtros!$C$5="",INDEX(tblFornos[Data],ROW()-1)<=Filtros!$C$5),OR(Filtros!$D$5="",INDEX(tblFornos[Forno],ROW()-1)=Filtros!$D$5),OR(Filtros!$E$5="",INDEX(tblFornos[Tipo],ROW()-1)=Filtros!$E$5),OR(Filtros!$F$5="",INDEX(tblFornos[Lado],ROW()-1)=Filtros!$F$5),OR(Filtros!$G$5="",DAY(INDEX(tblFornos[Data],ROW()-1))=Filtros!$G$5),OR(Filtros!$H$5="",MONTH(INDEX(tblFornos[Data],ROW()-1))=Filtros!$H$5),OR(Filtros!$I$5="",YEAR(INDEX(tblFornos[Data],ROW()-1))=Filtros!$I$5),OR(Filtros!$C$7="",ISNUMBER(SEARCH(Filtros!$C$7,INDEX(tblFornos[Forno],ROW()-1)&" "&INDEX(tblFornos[Tipo],ROW()-1)&" "&INDEX(tblFornos[Lado],ROW()-1)&" "&TEXT(INDEX(tblFornos[Data],ROW()-1),"dd/mm/yyyy"))))),1,0)) | AC4: =IFERROR(INDEX(tblFornos[ID],AGGREGATE(15,6,(ROW($AB$2:$AB$201)-1)/($AB$2:$AB$201=1),ROWS($AC$2:AC4))),"") | AD4: =IF($AC4="","",INDEX(tblFornos[Data],MATCH($AC4,tblFornos[ID],0))) | AE4: =IF($AC4="","",INDEX(tblFornos[Forno],MATCH($AC4,tblFornos[ID],0))) | AF4: =IF($AC4="","",INDEX(tblFornos[Tipo],MATCH($AC4,tblFornos[ID],0))) | AG4: =IF($AC4="","",INDEX(tblFornos[Lado],MATCH($AC4,tblFornos[ID],0)))
A5: 4 | B5: 46063 | C5: 103 | D5: Inspecao | E5: B | G5: Inspecao | J5: Abr | K5: 4 | L5: =COUNTIFS(tblFornos[Data],">="&DATE(YEAR(TODAY()),4,1),tblFornos[Data],"<"&DATE(YEAR(TODAY()),5,1)) | N5: =IFERROR(INDEX(tblFornos[Data],MATCH(LARGE(IF(COUNTIF($N$1:N4,tblFornos[Data])=0,COUNTIFS(tblFornos[Data],tblFornos[Data])),1),IF(COUNTIF($N$1:N4,tblFornos[Data])=0,COUNTIFS(tblFornos[Data],tblFornos[Data])),0)),"") | O5: =IF(N5="","",COUNTIFS(tblFornos[Data],N5)) | Q5: Inspecao | R5: =COUNTIFS(tblFornos[Tipo],"Inspecao") | T5: =IFERROR(INDEX(tblFornos[Forno],MATCH(LARGE(IF((tblFornos[Tipo]="Operacao")*(COUNTIF($T$1:T4,tblFornos[Forno])=0),COUNTIFS(tblFornos[Forno],tblFornos[Forno],tblFornos[Tipo],"Operacao")),1),IF((tblFornos[Tipo]="Operacao")*(COUNTIF($T$1:T4,tblFornos[Forno])=0),COUNTIFS(tblFornos[Forno],tblFornos[Forno],tblFornos[Tipo],"Operacao")),0)),"") | U5: =IF(T5="","",COUNTIFS(tblFornos[Forno],T5,tblFornos[Tipo],"Operacao")) | V5: =IFERROR(INDEX(tblFornos[Forno],MATCH(LARGE(IF((tblFornos[Tipo]="Manutencao")*(COUNTIF($V$1:V4,tblFornos[Forno])=0),COUNTIFS(tblFornos[Forno],tblFornos[Forno],tblFornos[Tipo],"Manutencao")),1),IF((tblFornos[Tipo]="Manutencao")*(COUNTIF($V$1:V4,tblFornos[Forno])=0),COUNTIFS(tblFornos[Forno],tblFornos[Forno],tblFornos[Tipo],"Manutencao")),0)),"") | W5: =IF(V5="","",COUNTIFS(tblFornos[Forno],V5,tblFornos[Tipo],"Manutencao")) | X5: =IFERROR(INDEX(tblFornos[Forno],MATCH(LARGE(IF((tblFornos[Tipo]="Falha")*(COUNTIF($X$1:X4,tblFornos[Forno])=0),COUNTIFS(tblFornos[Forno],tblFornos[Forno],tblFornos[Tipo],"Falha")),1),IF((tblFornos[Tipo]="Falha")*(COUNTIF($X$1:X4,tblFornos[Forno])=0),COUNTIFS(tblFornos[Forno],tblFornos[Forno],tblFornos[Tipo],"Falha")),0)),"") | Y5: =IF(X5="","",COUNTIFS(tblFornos[Forno],X5,tblFornos[Tipo],"Falha")) | Z5: =IFERROR(INDEX(tblFornos[Forno],MATCH(LARGE(IF((tblFornos[Tipo]="Inspecao")*(COUNTIF($Z$1:Z4,tblFornos[Forno])=0),COUNTIFS(tblFornos[Forno],tblFornos[Forno],tblFornos[Tipo],"Inspecao")),1),IF((tblFornos[Tipo]="Inspecao")*(COUNTIF($Z$1:Z4,tblFornos[Forno])=0),COUNTIFS(tblFornos[Forno],tblFornos[Forno],tblFornos[Tipo],"Inspecao")),0)),"") | AA5: =IF(Z5="","",COUNTIFS(tblFornos[Forno],Z5,tblFornos[Tipo],"Inspecao")) | AB5: =IF(ROW()-1>ROWS(tblFornos[ID]),0,IF(AND(OR(Filtros!$B$5="",INDEX(tblFornos[Data],ROW()-1)>=Filtros!$B$5),OR(Filtros!$C$5="",INDEX(tblFornos[Data],ROW()-1)<=Filtros!$C$5),OR(Filtros!$D$5="",INDEX(tblFornos[Forno],ROW()-1)=Filtros!$D$5),OR(Filtros!$E$5="",INDEX(tblFornos[Tipo],ROW()-1)=Filtros!$E$5),OR(Filtros!$F$5="",INDEX(tblFornos[Lado],ROW()-1)=Filtros!$F$5),OR(Filtros!$G$5="",DAY(INDEX(tblFornos[Data],ROW()-1))=Filtros!$G$5),OR(Filtros!$H$5="",MONTH(INDEX(tblFornos[Data],ROW()-1))=Filtros!$H$5),OR(Filtros!$I$5="",YEAR(INDEX(tblFornos[Data],ROW()-1))=Filtros!$I$5),OR(Filtros!$C$7="",ISNUMBER(SEARCH(Filtros!$C$7,INDEX(tblFornos[Forno],ROW()-1)&" "&INDEX(tblFornos[Tipo],ROW()-1)&" "&INDEX(tblFornos[Lado],ROW()-1)&" "&TEXT(INDEX(tblFornos[Data],ROW()-1),"dd/mm/yyyy"))))),1,0)) | AC5: =IFERROR(INDEX(tblFornos[ID],AGGREGATE(15,6,(ROW($AB$2:$AB$201)-1)/($AB$2:$AB$201=1),ROWS($AC$2:AC5))),"") | AD5: =IF($AC5="","",INDEX(tblFornos[Data],MATCH($AC5,tblFornos[ID],0))) | AE5: =IF($AC5="","",INDEX(tblFornos[Forno],MATCH($AC5,tblFornos[ID],0))) | AF5: =IF($AC5="","",INDEX(tblFornos[Tipo],MATCH($AC5,tblFornos[ID],0))) | AG5: =IF($AC5="","",INDEX(tblFornos[Lado],MATCH($AC5,tblFornos[ID],0)))
A6: 5 | B6: 46065 | C6: 102 | D6: Operacao | E6: A | J6: Mai | K6: 5 | L6: =COUNTIFS(tblFornos[Data],">="&DATE(YEAR(TODAY()),5,1),tblFornos[Data],"<"&DATE(YEAR(TODAY()),6,1)) | N6: =IFERROR(INDEX(tblFornos[Data],MATCH(LARGE(IF(COUNTIF($N$1:N5,tblFornos[Data])=0,COUNTIFS(tblFornos[Data],tblFornos[Data])),1),IF(COUNTIF($N$1:N5,tblFornos[Data])=0,COUNTIFS(tblFornos[Data],tblFornos[Data])),0)),"") | O6: =IF(N6="","",COUNTIFS(tblFornos[Data],N6)) | T6: =IFERROR(INDEX(tblFornos[Forno],MATCH(LARGE(IF((tblFornos[Tipo]="Operacao")*(COUNTIF($T$1:T5,tblFornos[Forno])=0),COUNTIFS(tblFornos[Forno],tblFornos[Forno],tblFornos[Tipo],"Operacao")),1),IF((tblFornos[Tipo]="Operacao")*(COUNTIF($T$1:T5,tblFornos[Forno])=0),COUNTIFS(tblFornos[Forno],tblFornos[Forno],tblFornos[Tipo],"Operacao")),0)),"") | U6: =IF(T6="","",COUNTIFS(tblFornos[Forno],T6,tblFornos[Tipo],"Operacao")) | V6: =IFERROR(INDEX(tblFornos[Forno],MATCH(LARGE(IF((tblFornos[Tipo]="Manutencao")*(COUNTIF($V$1:V5,tblFornos[Forno])=0),COUNTIFS(tblFornos[Forno],tblFornos[Forno],tblFornos[Tipo],"Manutencao")),1),IF((tblFornos[Tipo]="Manutencao")*(COUNTIF($V$1:V5,tblFornos[Forno])=0),COUNTIFS(tblFornos[Forno],tblFornos[Forno],tblFornos[Tipo],"Manutencao")),0)),"") | W6: =IF(V6="","",COUNTIFS(tblFornos[Forno],V6,tblFornos[Tipo],"Manutencao")) | X6: =IFERROR(INDEX(tblFornos[Forno],MATCH(LARGE(IF((tblFornos[Tipo]="Falha")*(COUNTIF($X$1:X5,tblFornos[Forno])=0),COUNTIFS(tblFornos[Forno],tblFornos[Forno],tblFornos[Tipo],"Falha")),1),IF((tblFornos[Tipo]="Falha")*(COUNTIF($X$1:X5,tblFornos[Forno])=0),COUNTIFS(tblFornos[Forno],tblFornos[Forno],tblFornos[Tipo],"Falha")),0)),"") | Y6: =IF(X6="","",COUNTIFS(tblFornos[Forno],X6,tblFornos[Tipo],"Falha")) | Z6: =IFERROR(INDEX(tblFornos[Forno],MATCH(LARGE(IF((tblFornos[Tipo]="Inspecao")*(COUNTIF($Z$1:Z5,tblFornos[Forno])=0),COUNTIFS(tblFornos[Forno],tblFornos[Forno],tblFornos[Tipo],"Inspecao")),1),IF((tblFornos[Tipo]="Inspecao")*(COUNTIF($Z$1:Z5,tblFornos[Forno])=0),COUNTIFS(tblFornos[Forno],tblFornos[Forno],tblFornos[Tipo],"Inspecao")),0)),"") | AA6: =IF(Z6="","",COUNTIFS(tblFornos[Forno],Z6,tblFornos[Tipo],"Inspecao")) | AB6: =IF(ROW()-1>ROWS(tblFornos[ID]),0,IF(AND(OR(Filtros!$B$5="",INDEX(tblFornos[Data],ROW()-1)>=Filtros!$B$5),OR(Filtros!$C$5="",INDEX(tblFornos[Data],ROW()-1)<=Filtros!$C$5),OR(Filtros!$D$5="",INDEX(tblFornos[Forno],ROW()-1)=Filtros!$D$5),OR(Filtros!$E$5="",INDEX(tblFornos[Tipo],ROW()-1)=Filtros!$E$5),OR(Filtros!$F$5="",INDEX(tblFornos[Lado],ROW()-1)=Filtros!$F$5),OR(Filtros!$G$5="",DAY(INDEX(tblFornos[Data],ROW()-1))=Filtros!$G$5),OR(Filtros!$H$5="",MONTH(INDEX(tblFornos[Data],ROW()-1))=Filtros!$H$5),OR(Filtros!$I$5="",YEAR(INDEX(tblFornos[Data],ROW()-1))=Filtros!$I$5),OR(Filtros!$C$7="",ISNUMBER(SEARCH(Filtros!$C$7,INDEX(tblFornos[Forno],ROW()-1)&" "&INDEX(tblFornos[Tipo],ROW()-1)&" "&INDEX(tblFornos[Lado],ROW()-1)&" "&TEXT(INDEX(tblFornos[Data],ROW()-1),"dd/mm/yyyy"))))),1,0)) | AC6: =IFERROR(INDEX(tblFornos[ID],AGGREGATE(15,6,(ROW($AB$2:$AB$201)-1)/($AB$2:$AB$201=1),ROWS($AC$2:AC6))),"") | AD6: =IF($AC6="","",INDEX(tblFornos[Data],MATCH($AC6,tblFornos[ID],0))) | AE6: =IF($AC6="","",INDEX(tblFornos[Forno],MATCH($AC6,tblFornos[ID],0))) | AF6: =IF($AC6="","",INDEX(tblFornos[Tipo],MATCH($AC6,tblFornos[ID],0))) | AG6: =IF($AC6="","",INDEX(tblFornos[Lado],MATCH($AC6,tblFornos[ID],0)))
A7: 6 | B7: 46084 | C7: 104 | D7: Manutencao | E7: A | J7: Jun | K7: 6 | L7: =COUNTIFS(tblFornos[Data],">="&DATE(YEAR(TODAY()),6,1),tblFornos[Data],"<"&DATE(YEAR(TODAY()),7,1)) | N7: =IFERROR(INDEX(tblFornos[Data],MATCH(LARGE(IF(COUNTIF($N$1:N6,tblFornos[Data])=0,COUNTIFS(tblFornos[Data],tblFornos[Data])),1),IF(COUNTIF($N$1:N6,tblFornos[Data])=0,COUNTIFS(tblFornos[Data],tblFornos[Data])),0)),"") | O7: =IF(N7="","",COUNTIFS(tblFornos[Data],N7)) | T7: =IFERROR(INDEX(tblFornos[Forno],MATCH(LARGE(IF((tblFornos[Tipo]="Operacao")*(COUNTIF($T$1:T6,tblFornos[Forno])=0),COUNTIFS(tblFornos[Forno],tblFornos[Forno],tblFornos[Tipo],"Operacao")),1),IF((tblFornos[Tipo]="Operacao")*(COUNTIF($T$1:T6,tblFornos[Forno])=0),COUNTIFS(tblFornos[Forno],tblFornos[Forno],tblFornos[Tipo],"Operacao")),0)),"") | U7: =IF(T7="","",COUNTIFS(tblFornos[Forno],T7,tblFornos[Tipo],"Operacao")) | V7: =IFERROR(INDEX(tblFornos[Forno],MATCH(LARGE(IF((tblFornos[Tipo]="Manutencao")*(COUNTIF($V$1:V6,tblFornos[Forno])=0),COUNTIFS(tblFornos[Forno],tblFornos[Forno],tblFornos[Tipo],"Manutencao")),1),IF((tblFornos[Tipo]="Manutencao")*(COUNTIF($V$1:V6,tblFornos[Forno])=0),COUNTIFS(tblFornos[Forno],tblFornos[Forno],tblFornos[Tipo],"Manutencao")),0)),"") | W7: =IF(V7="","",COUNTIFS(tblFornos[Forno],V7,tblFornos[Tipo],"Manutencao")) | X7: =IFERROR(INDEX(tblFornos[Forno],MATCH(LARGE(IF((tblFornos[Tipo]="Falha")*(COUNTIF($X$1:X6,tblFornos[Forno])=0),COUNTIFS(tblFornos[Forno],tblFornos[Forno],tblFornos[Tipo],"Falha")),1),IF((tblFornos[Tipo]="Falha")*(COUNTIF($X$1:X6,tblFornos[Forno])=0),COUNTIFS(tblFornos[Forno],tblFornos[Forno],tblFornos[Tipo],"Falha")),0)),"") | Y7: =IF(X7="","",COUNTIFS(tblFornos[Forno],X7,tblFornos[Tipo],"Falha")) | Z7: =IFERROR(INDEX(tblFornos[Forno],MATCH(LARGE(IF((tblFornos[Tipo]="Inspecao")*(COUNTIF($Z$1:Z6,tblFornos[Forno])=0),COUNTIFS(tblFornos[Forno],tblFornos[Forno],tblFornos[Tipo],"Inspecao")),1),IF((tblFornos[Tipo]="Inspecao")*(COUNTIF($Z$1:Z6,tblFornos[Forno])=0),COUNTIFS(tblFornos[Forno],tblFornos[Forno],tblFornos[Tipo],"Inspecao")),0)),"") | AA7: =IF(Z7="","",COUNTIFS(tblFornos[Forno],Z7,tblFornos[Tipo],"Inspecao")) | AB7: =IF(ROW()-1>ROWS(tblFornos[ID]),0,IF(AND(OR(Filtros!$B$5="",INDEX(tblFornos[Data],ROW()-1)>=Filtros!$B$5),OR(Filtros!$C$5="",INDEX(tblFornos[Data],ROW()-1)<=Filtros!$C$5),OR(Filtros!$D$5="",INDEX(tblFornos[Forno],ROW()-1)=Filtros!$D$5),OR(Filtros!$E$5="",INDEX(tblFornos[Tipo],ROW()-1)=Filtros!$E$5),OR(Filtros!$F$5="",INDEX(tblFornos[Lado],ROW()-1)=Filtros!$F$5),OR(Filtros!$G$5="",DAY(INDEX(tblFornos[Data],ROW()-1))=Filtros!$G$5),OR(Filtros!$H$5="",MONTH(INDEX(tblFornos[Data],ROW()-1))=Filtros!$H$5),OR(Filtros!$I$5="",YEAR(INDEX(tblFornos[Data],ROW()-1))=Filtros!$I$5),OR(Filtros!$C$7="",ISNUMBER(SEARCH(Filtros!$C$7,INDEX(tblFornos[Forno],ROW()-1)&" "&INDEX(tblFornos[Tipo],ROW()-1)&" "&INDEX(tblFornos[Lado],ROW()-1)&" "&TEXT(INDEX(tblFornos[Data],ROW()-1),"dd/mm/yyyy"))))),1,0)) | AC7: =IFERROR(INDEX(tblFornos[ID],AGGREGATE(15,6,(ROW($AB$2:$AB$201)-1)/($AB$2:$AB$201=1),ROWS($AC$2:AC7))),"") | AD7: =IF($AC7="","",INDEX(tblFornos[Data],MATCH($AC7,tblFornos[ID],0))) | AE7: =IF($AC7="","",INDEX(tblFornos[Forno],MATCH($AC7,tblFornos[ID],0))) | AF7: =IF($AC7="","",INDEX(tblFornos[Tipo],MATCH($AC7,tblFornos[ID],0))) | AG7: =IF($AC7="","",INDEX(tblFornos[Lado],MATCH($AC7,tblFornos[ID],0)))
A8: 7 | B8: 46096 | C8: 101 | D8: Operacao | E8: B | J8: Jul | K8: 7 | L8: =COUNTIFS(tblFornos[Data],">="&DATE(YEAR(TODAY()),7,1),tblFornos[Data],"<"&DATE(YEAR(TODAY()),8,1)) | N8: =IFERROR(INDEX(tblFornos[Data],MATCH(LARGE(IF(COUNTIF($N$1:N7,tblFornos[Data])=0,COUNTIFS(tblFornos[Data],tblFornos[Data])),1),IF(COUNTIF($N$1:N7,tblFornos[Data])=0,COUNTIFS(tblFornos[Data],tblFornos[Data])),0)),"") | O8: =IF(N8="","",COUNTIFS(tblFornos[Data],N8)) | T8: =IFERROR(INDEX(tblFornos[Forno],MATCH(LARGE(IF((tblFornos[Tipo]="Operacao")*(COUNTIF($T$1:T7,tblFornos[Forno])=0),COUNTIFS(tblFornos[Forno],tblFornos[Forno],tblFornos[Tipo],"Operacao")),1),IF((tblFornos[Tipo]="Operacao")*(COUNTIF($T$1:T7,tblFornos[Forno])=0),COUNTIFS(tblFornos[Forno],tblFornos[Forno],tblFornos[Tipo],"Operacao")),0)),"") | U8: =IF(T8="","",COUNTIFS(tblFornos[Forno],T8,tblFornos[Tipo],"Operacao")) | V8: =IFERROR(INDEX(tblFornos[Forno],MATCH(LARGE(IF((tblFornos[Tipo]="Manutencao")*(COUNTIF($V$1:V7,tblFornos[Forno])=0),COUNTIFS(tblFornos[Forno],tblFornos[Forno],tblFornos[Tipo],"Manutencao")),1),IF((tblFornos[Tipo]="Manutencao")*(COUNTIF($V$1:V7,tblFornos[Forno])=0),COUNTIFS(tblFornos[Forno],tblFornos[Forno],tblFornos[Tipo],"Manutencao")),0)),"") | W8: =IF(V8="","",COUNTIFS(tblFornos[Forno],V8,tblFornos[Tipo],"Manutencao")) | X8: =IFERROR(INDEX(tblFornos[Forno],MATCH(LARGE(IF((tblFornos[Tipo]="Falha")*(COUNTIF($X$1:X7,tblFornos[Forno])=0),COUNTIFS(tblFornos[Forno],tblFornos[Forno],tblFornos[Tipo],"Falha")),1),IF((tblFornos[Tipo]="Falha")*(COUNTIF($X$1:X7,tblFornos[Forno])=0),COUNTIFS(tblFornos[Forno],tblFornos[Forno],tblFornos[Tipo],"Falha")),0)),"") | Y8: =IF(X8="","",COUNTIFS(tblFornos[Forno],X8,tblFornos[Tipo],"Falha")) | Z8: =IFERROR(INDEX(tblFornos[Forno],MATCH(LARGE(IF((tblFornos[Tipo]="Inspecao")*(COUNTIF($Z$1:Z7,tblFornos[Forno])=0),COUNTIFS(tblFornos[Forno],tblFornos[Forno],tblFornos[Tipo],"Inspecao")),1),IF((tblFornos[Tipo]="Inspecao")*(COUNTIF($Z$1:Z7,tblFornos[Forno])=0),COUNTIFS(tblFornos[Forno],tblFornos[Forno],tblFornos[Tipo],"Inspecao")),0)),"") | AA8: =IF(Z8="","",COUNTIFS(tblFornos[Forno],Z8,tblFornos[Tipo],"Inspecao")) | AB8: =IF(ROW()-1>ROWS(tblFornos[ID]),0,IF(AND(OR(Filtros!$B$5="",INDEX(tblFornos[Data],ROW()-1)>=Filtros!$B$5),OR(Filtros!$C$5="",INDEX(tblFornos[Data],ROW()-1)<=Filtros!$C$5),OR(Filtros!$D$5="",INDEX(tblFornos[Forno],ROW()-1)=Filtros!$D$5),OR(Filtros!$E$5="",INDEX(tblFornos[Tipo],ROW()-1)=Filtros!$E$5),OR(Filtros!$F$5="",INDEX(tblFornos[Lado],ROW()-1)=Filtros!$F$5),OR(Filtros!$G$5="",DAY(INDEX(tblFornos[Data],ROW()-1))=Filtros!$G$5),OR(Filtros!$H$5="",MONTH(INDEX(tblFornos[Data],ROW()-1))=Filtros!$H$5),OR(Filtros!$I$5="",YEAR(INDEX(tblFornos[Data],ROW()-1))=Filtros!$I$5),OR(Filtros!$C$7="",ISNUMBER(SEARCH(Filtros!$C$7,INDEX(tblFornos[Forno],ROW()-1)&" "&INDEX(tblFornos[Tipo],ROW()-1)&" "&INDEX(tblFornos[Lado],ROW()-1)&" "&TEXT(INDEX(tblFornos[Data],ROW()-1),"dd/mm/yyyy"))))),1,0)) | AC8: =IFERROR(INDEX(tblFornos[ID],AGGREGATE(15,6,(ROW($AB$2:$AB$201)-1)/($AB$2:$AB$201=1),ROWS($AC$2:AC8))),"") | AD8: =IF($AC8="","",INDEX(tblFornos[Data],MATCH($AC8,tblFornos[ID],0))) | AE8: =IF($AC8="","",INDEX(tblFornos[Forno],MATCH($AC8,tblFornos[ID],0))) | AF8: =IF($AC8="","",INDEX(tblFornos[Tipo],MATCH($AC8,tblFornos[ID],0))) | AG8: =IF($AC8="","",INDEX(tblFornos[Lado],MATCH($AC8,tblFornos[ID],0)))
A9: 8 | B9: 46096 | C9: 105 | D9: Falha | E9: A | J9: Ago | K9: 8 | L9: =COUNTIFS(tblFornos[Data],">="&DATE(YEAR(TODAY()),8,1),tblFornos[Data],"<"&DATE(YEAR(TODAY()),9,1)) | N9: =IFERROR(INDEX(tblFornos[Data],MATCH(LARGE(IF(COUNTIF($N$1:N8,tblFornos[Data])=0,COUNTIFS(tblFornos[Data],tblFornos[Data])),1),IF(COUNTIF($N$1:N8,tblFornos[Data])=0,COUNTIFS(tblFornos[Data],tblFornos[Data])),0)),"") | O9: =IF(N9="","",COUNTIFS(tblFornos[Data],N9)) | T9: =IFERROR(INDEX(tblFornos[Forno],MATCH(LARGE(IF((tblFornos[Tipo]="Operacao")*(COUNTIF($T$1:T8,tblFornos[Forno])=0),COUNTIFS(tblFornos[Forno],tblFornos[Forno],tblFornos[Tipo],"Operacao")),1),IF((tblFornos[Tipo]="Operacao")*(COUNTIF($T$1:T8,tblFornos[Forno])=0),COUNTIFS(tblFornos[Forno],tblFornos[Forno],tblFornos[Tipo],"Operacao")),0)),"") | U9: =IF(T9="","",COUNTIFS(tblFornos[Forno],T9,tblFornos[Tipo],"Operacao")) | V9: =IFERROR(INDEX(tblFornos[Forno],MATCH(LARGE(IF((tblFornos[Tipo]="Manutencao")*(COUNTIF($V$1:V8,tblFornos[Forno])=0),COUNTIFS(tblFornos[Forno],tblFornos[Forno],tblFornos[Tipo],"Manutencao")),1),IF((tblFornos[Tipo]="Manutencao")*(COUNTIF($V$1:V8,tblFornos[Forno])=0),COUNTIFS(tblFornos[Forno],tblFornos[Forno],tblFornos[Tipo],"Manutencao")),0)),"") | W9: =IF(V9="","",COUNTIFS(tblFornos[Forno],V9,tblFornos[Tipo],"Manutencao")) | X9: =IFERROR(INDEX(tblFornos[Forno],MATCH(LARGE(IF((tblFornos[Tipo]="Falha")*(COUNTIF($X$1:X8,tblFornos[Forno])=0),COUNTIFS(tblFornos[Forno],tblFornos[Forno],tblFornos[Tipo],"Falha")),1),IF((tblFornos[Tipo]="Falha")*(COUNTIF($X$1:X8,tblFornos[Forno])=0),COUNTIFS(tblFornos[Forno],tblFornos[Forno],tblFornos[Tipo],"Falha")),0)),"") | Y9: =IF(X9="","",COUNTIFS(tblFornos[Forno],X9,tblFornos[Tipo],"Falha")) | Z9: =IFERROR(INDEX(tblFornos[Forno],MATCH(LARGE(IF((tblFornos[Tipo]="Inspecao")*(COUNTIF($Z$1:Z8,tblFornos[Forno])=0),COUNTIFS(tblFornos[Forno],tblFornos[Forno],tblFornos[Tipo],"Inspecao")),1),IF((tblFornos[Tipo]="Inspecao")*(COUNTIF($Z$1:Z8,tblFornos[Forno])=0),COUNTIFS(tblFornos[Forno],tblFornos[Forno],tblFornos[Tipo],"Inspecao")),0)),"") | AA9: =IF(Z9="","",COUNTIFS(tblFornos[Forno],Z9,tblFornos[Tipo],"Inspecao")) | AB9: =IF(ROW()-1>ROWS(tblFornos[ID]),0,IF(AND(OR(Filtros!$B$5="",INDEX(tblFornos[Data],ROW()-1)>=Filtros!$B$5),OR(Filtros!$C$5="",INDEX(tblFornos[Data],ROW()-1)<=Filtros!$C$5),OR(Filtros!$D$5="",INDEX(tblFornos[Forno],ROW()-1)=Filtros!$D$5),OR(Filtros!$E$5="",INDEX(tblFornos[Tipo],ROW()-1)=Filtros!$E$5),OR(Filtros!$F$5="",INDEX(tblFornos[Lado],ROW()-1)=Filtros!$F$5),OR(Filtros!$G$5="",DAY(INDEX(tblFornos[Data],ROW()-1))=Filtros!$G$5),OR(Filtros!$H$5="",MONTH(INDEX(tblFornos[Data],ROW()-1))=Filtros!$H$5),OR(Filtros!$I$5="",YEAR(INDEX(tblFornos[Data],ROW()-1))=Filtros!$I$5),OR(Filtros!$C$7="",ISNUMBER(SEARCH(Filtros!$C$7,INDEX(tblFornos[Forno],ROW()-1)&" "&INDEX(tblFornos[Tipo],ROW()-1)&" "&INDEX(tblFornos[Lado],ROW()-1)&" "&TEXT(INDEX(tblFornos[Data],ROW()-1),"dd/mm/yyyy"))))),1,0)) | AC9: =IFERROR(INDEX(tblFornos[ID],AGGREGATE(15,6,(ROW($AB$2:$AB$201)-1)/($AB$2:$AB$201=1),ROWS($AC$2:AC9))),"") | AD9: =IF($AC9="","",INDEX(tblFornos[Data],MATCH($AC9,tblFornos[ID],0))) | AE9: =IF($AC9="","",INDEX(tblFornos[Forno],MATCH($AC9,tblFornos[ID],0))) | AF9: =IF($AC9="","",INDEX(tblFornos[Tipo],MATCH($AC9,tblFornos[ID],0))) | AG9: =IF($AC9="","",INDEX(tblFornos[Lado],MATCH($AC9,tblFornos[ID],0)))
A10: 9 | B10: 46114 | C10: 103 | D10: Operacao | E10: B | J10: Set | K10: 9 | L10: =COUNTIFS(tblFornos[Data],">="&DATE(YEAR(TODAY()),9,1),tblFornos[Data],"<"&DATE(YEAR(TODAY()),10,1)) | N10: =IFERROR(INDEX(tblFornos[Data],MATCH(LARGE(IF(COUNTIF($N$1:N9,tblFornos[Data])=0,COUNTIFS(tblFornos[Data],tblFornos[Data])),1),IF(COUNTIF($N$1:N9,tblFornos[Data])=0,COUNTIFS(tblFornos[Data],tblFornos[Data])),0)),"") | O10: =IF(N10="","",COUNTIFS(tblFornos[Data],N10)) | T10: =IFERROR(INDEX(tblFornos[Forno],MATCH(LARGE(IF((tblFornos[Tipo]="Operacao")*(COUNTIF($T$1:T9,tblFornos[Forno])=0),COUNTIFS(tblFornos[Forno],tblFornos[Forno],tblFornos[Tipo],"Operacao")),1),IF((tblFornos[Tipo]="Operacao")*(COUNTIF($T$1:T9,tblFornos[Forno])=0),COUNTIFS(tblFornos[Forno],tblFornos[Forno],tblFornos[Tipo],"Operacao")),0)),"") | U10: =IF(T10="","",COUNTIFS(tblFornos[Forno],T10,tblFornos[Tipo],"Operacao")) | V10: =IFERROR(INDEX(tblFornos[Forno],MATCH(LARGE(IF((tblFornos[Tipo]="Manutencao")*(COUNTIF($V$1:V9,tblFornos[Forno])=0),COUNTIFS(tblFornos[Forno],tblFornos[Forno],tblFornos[Tipo],"Manutencao")),1),IF((tblFornos[Tipo]="Manutencao")*(COUNTIF($V$1:V9,tblFornos[Forno])=0),COUNTIFS(tblFornos[Forno],tblFornos[Forno],tblFornos[Tipo],"Manutencao")),0)),"") | W10: =IF(V10="","",COUNTIFS(tblFornos[Forno],V10,tblFornos[Tipo],"Manutencao")) | X10: =IFERROR(INDEX(tblFornos[Forno],MATCH(LARGE(IF((tblFornos[Tipo]="Falha")*(COUNTIF($X$1:X9,tblFornos[Forno])=0),COUNTIFS(tblFornos[Forno],tblFornos[Forno],tblFornos[Tipo],"Falha")),1),IF((tblFornos[Tipo]="Falha")*(COUNTIF($X$1:X9,tblFornos[Forno])=0),COUNTIFS(tblFornos[Forno],tblFornos[Forno],tblFornos[Tipo],"Falha")),0)),"") | Y10: =IF(X10="","",COUNTIFS(tblFornos[Forno],X10,tblFornos[Tipo],"Falha")) | Z10: =IFERROR(INDEX(tblFornos[Forno],MATCH(LARGE(IF((tblFornos[Tipo]="Inspecao")*(COUNTIF($Z$1:Z9,tblFornos[Forno])=0),COUNTIFS(tblFornos[Forno],tblFornos[Forno],tblFornos[Tipo],"Inspecao")),1),IF((tblFornos[Tipo]="Inspecao")*(COUNTIF($Z$1:Z9,tblFornos[Forno])=0),COUNTIFS(tblFornos[Forno],tblFornos[Forno],tblFornos[Tipo],"Inspecao")),0)),"") | AA10: =IF(Z10="","",COUNTIFS(tblFornos[Forno],Z10,tblFornos[Tipo],"Inspecao")) | AB10: =IF(ROW()-1>ROWS(tblFornos[ID]),0,IF(AND(OR(Filtros!$B$5="",INDEX(tblFornos[Data],ROW()-1)>=Filtros!$B$5),OR(Filtros!$C$5="",INDEX(tblFornos[Data],ROW()-1)<=Filtros!$C$5),OR(Filtros!$D$5="",INDEX(tblFornos[Forno],ROW()-1)=Filtros!$D$5),OR(Filtros!$E$5="",INDEX(tblFornos[Tipo],ROW()-1)=Filtros!$E$5),OR(Filtros!$F$5="",INDEX(tblFornos[Lado],ROW()-1)=Filtros!$F$5),OR(Filtros!$G$5="",DAY(INDEX(tblFornos[Data],ROW()-1))=Filtros!$G$5),OR(Filtros!$H$5="",MONTH(INDEX(tblFornos[Data],ROW()-1))=Filtros!$H$5),OR(Filtros!$I$5="",YEAR(INDEX(tblFornos[Data],ROW()-1))=Filtros!$I$5),OR(Filtros!$C$7="",ISNUMBER(SEARCH(Filtros!$C$7,INDEX(tblFornos[Forno],ROW()-1)&" "&INDEX(tblFornos[Tipo],ROW()-1)&" "&INDEX(tblFornos[Lado],ROW()-1)&" "&TEXT(INDEX(tblFornos[Data],ROW()-1),"dd/mm/yyyy"))))),1,0)) | AC10: =IFERROR(INDEX(tblFornos[ID],AGGREGATE(15,6,(ROW($AB$2:$AB$201)-1)/($AB$2:$AB$201=1),ROWS($AC$2:AC10))),"") | AD10: =IF($AC10="","",INDEX(tblFornos[Data],MATCH($AC10,tblFornos[ID],0))) | AE10: =IF($AC10="","",INDEX(tblFornos[Forno],MATCH($AC10,tblFornos[ID],0))) | AF10: =IF($AC10="","",INDEX(tblFornos[Tipo],MATCH($AC10,tblFornos[ID],0))) | AG10: =IF($AC10="","",INDEX(tblFornos[Lado],MATCH($AC10,tblFornos[ID],0)))
